Workbook

Sheet Summary
A1: FRAMS testing summary
A2: 18 October 2026
A4: Category | B4: Executed | C4: Passed | D4: Failed | E4: Blocked | F4: Not Executed
A5: Unit Testing | B5: =COUNTIF('All Test Cases'!B:B,A5) | C5: =COUNTIFS('All Test Cases'!B:B,A5,'All Test Cases'!F:F,"PASS") | D5: =COUNTIFS('All Test Cases'!B:B,A5,'All Test Cases'!F:F,"FAIL") | E5: =COUNTIFS('All Test Cases'!B:B,A5,'All Test Cases'!F:F,"BLOCKED") | F5: =COUNTIFS('All Test Cases'!B:B,A5,'All Test Cases'!F:F,"NOT EXECUTED")
A6: Integration Testing | B6: =COUNTIF('All Test Cases'!B:B,A6) | C6: =COUNTIFS('All Test Cases'!B:B,A6,'All Test Cases'!F:F,"PASS") | D6: =COUNTIFS('All Test Cases'!B:B,A6,'All Test Cases'!F:F,"FAIL") | E6: =COUNTIFS('All Test Cases'!B:B,A6,'All Test Cases'!F:F,"BLOCKED") | F6: =COUNTIFS('All Test Cases'!B:B,A6,'All Test Cases'!F:F,"NOT EXECUTED")
A7: System Testing | B7: =COUNTIF('All Test Cases'!B:B,A7) | C7: =COUNTIFS('All Test Cases'!B:B,A7,'All Test Cases'!F:F,"PASS") | D7: =COUNTIFS('All Test Cases'!B:B,A7,'All Test Cases'!F:F,"FAIL") | E7: =COUNTIFS('All Test Cases'!B:B,A7,'All Test Cases'!F:F,"BLOCKED") | F7: =COUNTIFS('All Test Cases'!B:B,A7,'All Test Cases'!F:F,"NOT EXECUTED")
A8: Security Testing | B8: =COUNTIF('All Test Cases'!B:B,A8) | C8: =COUNTIFS('All Test Cases'!B:B,A8,'All Test Cases'!F:F,"PASS") | D8: =COUNTIFS('All Test Cases'!B:B,A8,'All Test Cases'!F:F,"FAIL") | E8: =COUNTIFS('All Test Cases'!B:B,A8,'All Test Cases'!F:F,"BLOCKED") | F8: =COUNTIFS('All Test Cases'!B:B,A8,'All Test Cases'!F:F,"NOT EXECUTED")
A9: Penetration Testing | B9: =COUNTIF('All Test Cases'!B:B,A9) | C9: =COUNTIFS('All Test Cases'!B:B,A9,'All Test Cases'!F:F,"PASS") | D9: =COUNTIFS('All Test Cases'!B:B,A9,'All Test Cases'!F:F,"FAIL") | E9: =COUNTIFS('All Test Cases'!B:B,A9,'All Test Cases'!F:F,"BLOCKED") | F9: =COUNTIFS('All Test Cases'!B:B,A9,'All Test Cases'!F:F,"NOT EXECUTED")
A10: PayMongo Testing | B10: =COUNTIF('All Test Cases'!B:B,A10) | C10: =COUNTIFS('All Test Cases'!B:B,A10,'All Test Cases'!F:F,"PASS") | D10: =COUNTIFS('All Test Cases'!B:B,A10,'All Test Cases'!F:F,"FAIL") | E10: =COUNTIFS('All Test Cases'!B:B,A10,'All Test Cases'!F:F,"BLOCKED") | F10: =COUNTIFS('All Test Cases'!B:B,A10,'All Test Cases'!F:F,"NOT EXECUTED")
A11: TOTAL | B11: =SUM(B5:B10) | C11: =SUM(C5:C10) | D11: =SUM(D5:D10) | E11: =SUM(E5:E10) | F11: =SUM(F5:F10)
A13: Pass rate | B13: =IF((C11+D11)=0,0,C11/(C11+D11)) | C13: Denominator is passed plus failed. Blocked cases are excluded.
A15: Distinct test cases | B15: =COUNTA('All Test Cases'!A5:A500)
A17: Major confirmed findings
A18: F-001 zero or negative term is charged as one month; F-002 unencoded expense message; F-003 loan status changes without CSRF; F-004 security headers missing; F-005 local error display shows a filesystem path; F-007 loans outstanding card does not subtract payments.
A20: Limitations
A21: Live PayMongo payment creation and inbound webhook delivery were blocked. The live key was not used.

Sheet All Test Cases
A4: Test Case ID | B4: Category | C4: Scenario | D4: Expected Result | E4: Actual Result | F4: Status | G4: Evidence Filename | H4: Remarks
A5: UT-001 | B5: Unit Testing | C5: Standard monthly interest rate | D5: 5.0 percent | E5: 5 | F5: PASS | G5: logs/cli_test_execution.log
A6: UT-002 | B6: Unit Testing | C6: Twelve-month interest breakdown | D6: monthly 500.00, interest 6000.00, payable 16000.00 | E6: {"monthly_interest":500,"total_interest":6000,"total_payable":16000} | F6: PASS | G6: logs/cli_test_execution.log | H6: Formula: monthly = principal x rate/100; total interest = monthly x months; payable = principal + total interest.
A7: UT-003 | B7: Unit Testing | C7: Three-month interest breakdown | D7: monthly 500.00, interest 1500.00, payable 11500.00 | E7: {"monthly_interest":500,"total_interest":1500,"total_payable":11500} | F7: PASS | G7: logs/cli_test_execution.log
A8: UT-004 | B8: Unit Testing | C8: Zero principal | D8: all amounts 0.00 | E8: {"monthly_interest":0,"total_interest":0,"total_payable":0} | F8: PASS | G8: logs/cli_test_execution.log
A9: UT-005 | B9: Unit Testing | C9: Negative principal | D9: payable is 0.00 | E9: {"monthly_interest":0,"total_interest":0,"total_payable":0} | F9: PASS | G9: logs/cli_test_execution.log | H9: The implementation clamps principal with max(0, amount) instead of throwing.
A10: UT-006 | B10: Unit Testing | C10: Negative interest rate | D10: interest 0.00 and payable 8000.00 | E10: {"monthly_interest":0,"total_interest":0,"total_payable":8000} | F10: PASS | G10: logs/cli_test_execution.log | H10: Negative rates are clamped to zero.
A11: UT-007 | B11: Unit Testing | C11: Zero loan duration | D11: Invalid duration is rejected or does not create one month of interest. | E11: {"monthly_interest":500,"total_interest":500,"total_payable":10500} | F11: FAIL | G11: logs/cli_test_execution.log | H11: max(1, term) coerces zero months to one month and charges interest of 500.00.
A12: UT-008 | B12: Unit Testing | C12: Negative loan duration | D12: Invalid duration does not produce a one-month charge. | E12: {"monthly_interest":500,"total_interest":500,"total_payable":10500} | F12: FAIL | G12: logs/cli_test_execution.log | H12: Same coercion as UT-007.
A13: UT-009 | B13: Unit Testing | C13: Decimal rounding | D13: monthly 5.02, interest 15.05, payable 115.38 | E13: {"monthly_interest":5.02,"total_interest":15.05,"total_payable":115.38} | F13: PASS | G13: logs/cli_test_execution.log | H13: Each returned field is rounded separately. Rounded monthly interest times months is 15.06, while total interest remains 15.05.
A14: UT-010 | B14: Unit Testing | C14: Policy maximum principal | D14: monthly 25000.00, interest 300000.00, payable 800000.00 | E14: {"monthly_interest":25000,"total_interest":300000,"total_payable":800000} | F14: PASS | G14: logs/cli_test_execution.log
A15: UT-011 | B15: Unit Testing | C15: Loan term label parsing | D15: 12 | E15: 12 | F15: PASS | G15: logs/cli_test_execution.log
A16: UT-012 | B16: Unit Testing | C16: Non-numeric loan term | D16: 0 | E16: 0 | F16: PASS | G16: logs/cli_test_execution.log
A17: UT-013 | B17: Unit Testing | C17: Numeric zero term parsing | D17: The parser returns 1 because numeric input uses max(1, value). | E17: 1 | F17: PASS | G17: logs/cli_test_execution.log | H17: This matches the coercion observed in UT-007.
A18: UT-014 | B18: Unit Testing | C18: Payment frequency normalization | D18: semi-monthly, weekly, monthly | E18: checked three labels | F18: PASS | G18: logs/cli_test_execution.log
A19: UT-015 | B19: Unit Testing | C19: Installment counts | D19: 3, 12, 6, and 60 | E19: monthly 3, weekly 12, semi-monthly 6, daily 60 | F19: PASS | G19: logs/cli_test_execution.log | H19: Daily count without explicit dates is term months times 30.
A20: UT-016 | B20: Unit Testing | C20: Monthly due date | D20: 2026-03-15 | E20: 2026-03-15 | F20: PASS | G20: logs/cli_test_execution.log
A21: UT-017 | B21: Unit Testing | C21: Penalty rates by frequency | D21: 1, 2, 3, and 5 percent | E21: 1, 2, 3, 5 | F21: PASS | G21: logs/cli_test_execution.log
A22: UT-018 | B22: Unit Testing | C22: Installment amount from total payable | D22: 3833.33 | E22: 3833.33 | F22: PASS | G22: logs/cli_test_execution.log
A23: UT-019 | B23: Unit Testing | C23: Scheduled installment override | D23: 4000.00 | E23: 4000 | F23: PASS | G23: logs/cli_test_execution.log
A24: UT-020 | B24: Unit Testing | C24: Password policy | D24: true, false, false | E24: valid accepted; short and alphanumeric rejected | F24: PASS | G24: logs/cli_test_execution.log
A25: UT-021 | B25: Unit Testing | C25: Password verification | D25: hash matches; wrong password and plaintext storage do not | E25: hash match true; plaintext comparison false | F25: PASS | G25: logs/cli_test_execution.log
A26: UT-022 | B26: Unit Testing | C26: CSRF token comparison | D26: true, false, false | E26: matching accepted; mismatch and empty rejected | F26: PASS | G26: logs/cli_test_execution.log
A27: UT-023 | B27: Unit Testing | C27: Valid webhook signature | D27: true | E27: true | F27: PASS | G27: logs/cli_test_execution.log | H27: Local function test. No PayMongo request.
A28: UT-024 | B28: Unit Testing | C28: Invalid webhook signature | D28: false | E28: false | F28: PASS | G28: logs/cli_test_execution.log
A29: UT-025 | B29: Unit Testing | C29: Missing webhook signature | D29: false | E29: false | F29: PASS | G29: logs/cli_test_execution.log
A30: UT-026 | B30: Unit Testing | C30: Expired webhook timestamp | D30: false | E30: false | F30: PASS | G30: logs/cli_test_execution.log
A31: UT-027 | B31: Unit Testing | C31: Malformed webhook JSON | D31: null | E31: null | F31: PASS | G31: logs/cli_test_execution.log
A32: UT-028 | B32: Unit Testing | C32: Valid webhook event parse | D32: id and type extracted | E32: evt_parse payment.paid | F32: PASS | G32: logs/cli_test_execution.log
A33: UT-029 | B33: Unit Testing | C33: Webhook amount match | D33: true then false | E33: match/no-match | F33: PASS | G33: logs/cli_test_execution.log
A34: UT-030 | B34: Unit Testing | C34: QR image URL allow list | D34: only the PayMongo HTTPS URL is safe | E34: safe=yes unsafe-accepted=no | F34: PASS | G34: logs/cli_test_execution.log
A35: UT-031 | B35: Unit Testing | C35: Proposed monthly payment | D35: 1333.33 | E35: 1333.33 | F35: PASS | G35: logs/cli_test_execution.log | H35: 16000 / 12 = 1333.333..., rounded to 1333.33.
A36: UT-032 | B36: Unit Testing | C36: Maximum principal from payment | D36: approximately 9999.98 | E36: 9999.98 | F36: PASS | G36: logs/cli_test_execution.log | H36: Rounding of the forward payment prevents an exact 10000 reverse value.
A37: UT-033 | B37: Unit Testing | C37: Loan amount policy clamp | D37: 3000.00 | E37: 3000 | F37: PASS | G37: logs/cli_test_execution.log
A38: UT-034 | B38: Unit Testing | C38: Employment length parsing | D38: 24 and 2 | E38: 24 and 2 | F38: PASS | G38: logs/cli_test_execution.log
A39: UT-035 | B39: Unit Testing | C39: Eligible affordability estimate | D39: Eligible | E39: Eligible | F39: PASS | G39: logs/cli_test_execution.log | H39: DTI after observed: 11.11
A40: UT-036 | B40: Unit Testing | C40: Incomplete eligibility input | D40: Not Eligible and status_code incomplete | E40: Not Eligible/incomplete | F40: PASS | G40: logs/cli_test_execution.log
A41: UT-037 | B41: Unit Testing | C41: DTI above policy limit | D41: Not Eligible | E41: Not Eligible DTI 66.67 | F41: PASS | G41: logs/cli_test_execution.log
A42: UT-038 | B42: Unit Testing | C42: Conditional eligibility | D42: Conditionally Eligible | E42: Conditionally Eligible | F42: PASS | G42: logs/cli_test_execution.log
A43: UT-039 | B43: Unit Testing | C43: Existing debt blocks the wizard | D43: a non-empty blocking message | E43: blocked | F43: PASS | G43: logs/cli_test_execution.log
...

Sheet Security Findings
A1: Finding ID | B1: Category | C1: Affected component | D1: Description | E1: Severity | F1: Evidence | G1: Reproduction summary | H1: Recommendation | I1: Retest status
A2: F-001 | B2: Unit Testing | C2: calculateLoanInterestBreakdown | D2: A zero or negative loan term is coerced to one month, so the calculator charges one month of interest instead of rejecting the duration. | E2: Low | F2: 01_Unit_Testing/logs/cli_test_execution.log | G2: Call calculateLoanInterestBreakdown(10000, 5, 0). Observed total interest 500.00 and total payable 10500.00. | H2: Reject a term less than 1 at the calculator and at the application form before interest is stored. | I2: Not retested. Application code was not changed.
A3: F-002 | B3: Security Testing | C3: expenses_lending.php message query parameter | D3: The expenses page prints the message query parameter without encoding, so an authenticated user can be sent a link that injects HTML. | E3: Medium | F3: 04_Security_Testing/logs/http_test_execution.log | G3: Sign in as an administrator on the isolated server and open expenses_lending.php?message=FRAMSXSS<b>probe</b>&type=success. The response contains the raw b tag. | H3: Encode $message and $messageType with htmlspecialchars before output. Apply the same fix on the other pages that echo those variables. | I3: Not retested. Application code was not changed.
A4: F-003 | B4: Security Testing | C4: loans_lending.php update_status | D4: An authenticated administrator request can change a loan status without a CSRF token. | E4: Medium | F4: 04_Security_Testing/logs/http_test_execution.log | G4: Sign in as the synthetic administrator and POST update_status, loan_id, and status=Overdue to loans_lending.php without _csrf_token. The loan status changes. | H4: Call csrfRequireValid() before update_status, as payments_lending.php already does. | I4: Not retested. The synthetic loan status is restored after the demonstration. Application code was not changed.
A5: F-004 | B5: Security Testing | C5: HTTP response headers | D5: Login responses do not set X-Frame-Options, X-Content-Type-Options, Content-Security-Policy, Referrer-Policy. | E5: Low | F5: 04_Security_Testing/logs/http_test_execution.log | G5: GET login_lending.php on the isolated server and inspect the response headers. | H5: Send the missing headers from a shared include used by every page. | I5: Not retested. Application code was not changed.
A6: F-005 | B6: Security Testing | C6: users_lending.php | D6: With APP_ENV=local, display_errors is on. The user list passes a null email to htmlspecialchars and prints a deprecation warning that includes the application filesystem path. | E6: Low | F6: 04_Security_Testing/screenshots/SEC-018_error_disclosure.png | G6: Sign in as the synthetic administrator on the isolated server and open users_lending.php. The email column shows the deprecation text and path. | H6: Pass an empty string when email is null, and set APP_ENV=production with display_errors off on any shared server. | I6: Not retested. Application code was not changed.
A7: F-006 | B7: PayMongo Testing | C7: PayMongo configuration | D7: The project .env sets PAYMONGO_MODE=live and contains a live secret key and live public key. PAYMONGO_WEBHOOK_SECRET is empty. No live API request was sent during this test. | E7: High | F7: 06_PayMongo_Testing/logs/environment_probe.txt | G7: Read the configuration keys without printing their values. Mode is live, the secret key prefix is sk_live, and the webhook secret is empty. | H7: Use test keys and PAYMONGO_MODE=test on this local workstation. Configure the matching webhook secret before accepting QR Ph events. Do not commit .env. | I7: Not changed. Live credentials were not used.
A8: F-007 | B8: System Testing | C8: loans_lending.php outstanding statistic | D8: The loans page outstanding figure sums total_payable for loans whose stored status is not Paid. It does not subtract recorded payments. After 10,416.66 in collections the card still showed 17,000.00, while the reports page outstanding was 6,583.34. | E8: Medium | F8: 03_System_Testing/screenshots/ST-006_admin_loans.png | G8: Record partial payments on the isolated loans and compare the loans page outstanding card with the reports page outstanding card. | H8: Calculate outstanding as total payable minus recorded payments, consistent with calculateLoanBalanceSummary. | I8: Not retested. Application code was not changed.

Sheet Evidence Register
A1: Evidence ID | B1: Testing Category | C1: Related Test Case ID | D1: Filename | E1: Evidence Type | F1: Description | G1: Execution Date | H1: Evidence Status
A2: E-001 | B2: Unit Testing | D2: cli_test_execution.log | E2: log | F2: 01_Unit_Testing/logs/cli_test_execution.log | G2: 18 October 2026 | H2: Present
A3: E-002 | B3: Unit Testing | D3: report.md | E3: md | F3: 01_Unit_Testing/report.md | G3: 18 October 2026 | H3: Present
A4: E-003 | B4: Unit Testing | D4: NO_BROWSER_SCREENSHOT.txt | E4: txt | F4: 01_Unit_Testing/screenshots/NO_BROWSER_SCREENSHOT.txt | G4: 18 October 2026 | H4: Present
A5: E-004 | B5: Unit Testing | D5: cli_results.json | E5: json | F5: 01_Unit_Testing/test_results/cli_results.json | G5: 18 October 2026 | H5: Present
A6: E-005 | B6: Unit Testing | D6: published_results.json | E6: json | F6: 01_Unit_Testing/test_results/published_results.json | G6: 18 October 2026 | H6: Present
A7: E-006 | B7: Integration Testing | D7: cli_test_execution.log | E7: log | F7: 02_Integration_Testing/logs/cli_test_execution.log | G7: 18 October 2026 | H7: Present
A8: E-007 | B8: Integration Testing | D8: report.md | E8: md | F8: 02_Integration_Testing/report.md | G8: 18 October 2026 | H8: Present
A9: E-008 | B9: Integration Testing | D9: NO_BROWSER_SCREENSHOT.txt | E9: txt | F9: 02_Integration_Testing/screenshots/NO_BROWSER_SCREENSHOT.txt | G9: 18 October 2026 | H9: Present
A10: E-009 | B10: Integration Testing | D10: cli_results.json | E10: json | F10: 02_Integration_Testing/test_results/cli_results.json | G10: 18 October 2026 | H10: Present
A11: E-010 | B11: Integration Testing | D11: published_results.json | E11: json | F11: 02_Integration_Testing/test_results/published_results.json | G11: 18 October 2026 | H11: Present
A12: E-011 | B12: System Testing | D12: http_test_execution.log | E12: log | F12: 03_System_Testing/logs/http_test_execution.log | G12: 18 October 2026 | H12: Present
A13: E-012 | B13: System Testing | D13: loans_page.html | E13: html | F13: 03_System_Testing/logs/loans_page.html | G13: 18 October 2026 | H13: Present
A14: E-013 | B14: System Testing | D14: report.md | E14: md | F14: 03_System_Testing/report.md | G14: 18 October 2026 | H14: Present
A15: E-014 | B15: System Testing | C15: ST-001 | D15: ST-001_staff_login.png | E15: png | F15: 03_System_Testing/screenshots/ST-001_staff_login.png | G15: 18 October 2026 | H15: Present
A16: E-015 | B16: System Testing | C16: ST-002 | D16: ST-002_invalid_login.png | E16: png | F16: 03_System_Testing/screenshots/ST-002_invalid_login.png | G16: 18 October 2026 | H16: Present
A17: E-016 | B17: System Testing | C17: ST-004 | D17: ST-004_admin_dashboard.png | E17: png | F17: 03_System_Testing/screenshots/ST-004_admin_dashboard.png | G17: 18 October 2026 | H17: Present
A18: E-017 | B18: System Testing | C18: ST-005 | D18: ST-005_admin_clients.png | E18: png | F18: 03_System_Testing/screenshots/ST-005_admin_clients.png | G18: 18 October 2026 | H18: Present
A19: E-018 | B19: System Testing | C19: ST-006 | D19: ST-006_admin_loans.png | E19: png | F19: 03_System_Testing/screenshots/ST-006_admin_loans.png | G19: 18 October 2026 | H19: Present
A20: E-019 | B20: System Testing | C20: ST-006 | D20: ST-006_admin_loans_table.png | E20: png | F20: 03_System_Testing/screenshots/ST-006_admin_loans_table.png | G20: 18 October 2026 | H20: Present
A21: E-020 | B21: System Testing | C21: ST-007 | D21: ST-007_admin_payments.png | E21: png | F21: 03_System_Testing/screenshots/ST-007_admin_payments.png | G21: 18 October 2026 | H21: Present
A22: E-021 | B22: System Testing | C22: ST-008 | D22: ST-008_admin_reports.png | E22: png | F22: 03_System_Testing/screenshots/ST-008_admin_reports.png | G22: 18 October 2026 | H22: Present
A23: E-022 | B23: System Testing | C23: ST-009 | D23: ST-009_admin_users.png | E23: png | F23: 03_System_Testing/screenshots/ST-009_admin_users.png | G23: 18 October 2026 | H23: Present
A24: E-023 | B24: System Testing | C24: ST-010 | D24: ST-010_collector_dashboard.png | E24: png | F24: 03_System_Testing/screenshots/ST-010_collector_dashboard.png | G24: 18 October 2026 | H24: Present
A25: E-024 | B25: System Testing | C25: ST-014 | D25: ST-014_borrower_dashboard.png | E25: png | F25: 03_System_Testing/screenshots/ST-014_borrower_dashboard.png | G25: 18 October 2026 | H25: Present
A26: E-025 | B26: System Testing | C26: ST-015 | D26: ST-015_borrower_loan.png | E26: png | F26: 03_System_Testing/screenshots/ST-015_borrower_loan.png | G26: 18 October 2026 | H26: Present
... A29: E-028 | B29: System Testing | C29: ST-020 | D29: ST-020_collector_forbidden.png | E29: png | F29: 03_System_Testing/screenshots/ST-020_collector_forbidden.png | G29: 18 October 2026 | H29: Present
A30: E-029 | B30: System Testing | D30: http_results.json | E30: json | F30: 03_System_Testing/test_results/http_results.json | G30: 18 October 2026 | H30: Present
A31: E-030 | B31: System Testing | D31: published_results.json | E31: json | F31: 03_System_Testing/test_results/published_results.json | G31: 18 October 2026 | H31: Present
A32: E-031 | B32: Security Testing | D32: cli_test_execution.log | E32: log | F32: 04_Security_Testing/logs/cli_test_execution.log | G32: 18 October 2026 | H32: Present
A33: E-032 | B33: Security Testing | D33: http_test_execution.log | E33: log | F33: 04_Security_Testing/logs/http_test_execution.log | G33: 18 October 2026 | H33: Present
A34: E-033 | B34: Security Testing | D34: sec010_alert_innerhtml.txt | E34: txt | F34: 04_Security_Testing/logs/sec010_alert_innerhtml.txt | G34: 18 October 2026 | H34: Present
A35: E-034 | B35: Security Testing | D35: report.md | E35: md | F35: 04_Security_Testing/report.md | G35: 18 October 2026 | H35: Present
A36: E-035 | B36: Security Testing | C36: SEC-010 | D36: SEC-010_reflected_message.png | E36: png | F36: 04_Security_Testing/screenshots/SEC-010_reflected_message.png | G36: 18 October 2026 | H36: Present
A37: E-036 | B37: Security Testing | C37: SEC-014 | D37: SEC-014_dashboard_overdue_count.png | E37: png | F37: 04_Security_Testing/screenshots/SEC-014_dashboard_overdue_count.png | G37: 18 October 2026 | H37: Present
A38: E-037 | B38: Security Testing | C38: SEC-014 | D38: SEC-014_status_visible_to_borrower.png | E38: png | F38: 04_Security_Testing/screenshots/SEC-014_status_visible_to_borrower.png | G38: 18 October 2026 | H38: Present
A39: E-038 | B39: Security Testing | C39: SEC-018 | D39: SEC-018_error_disclosure.png | E39: png | F39: 04_Security_Testing/screenshots/SEC-018_error_disclosure.png | G39: 18 October 2026 | H39: Present
A40: E-039 | B40: Security Testing | D40: cli_results.json | E40: json | F40: 04_Security_Testing/test_results/cli_results.json | G40: 18 October 2026 | H40: Present
A41: E-040 | B41: Security Testing | D41: http_results.json | E41: json | F41: 04_Security_Testing/test_results/http_results.json | G41: 18 October 2026 | H41: Present
A42: E-041 | B42: Security Testing | D42: published_results.json | E42: json | F42: 04_Security_Testing/test_results/published_results.json | G42: 18 October 2026 | H42: Present
...
